<?xml version="1.0" ?>
<robot name="sample_robot" xmlns:xacro="http://www.ros.org/wiki/xacro">
<xacro:include filename="$(find gazebo_example)/urdf/sample_robot.gazebo"/>

<gazebo>
  <plugin filename="libgazebo_ros_diff_drive.so" name="differential_drive_controller">
    <legacyMode>true</legacyMode>
    <alwaysOn>true</alwaysOn>
    <updateRate>20</updateRate>
    <leftJoint>joint_left_wheel</leftJoint>
    <rightJoint>joint_right_wheel</rightJoint>
    <wheelSeparation>0.3</wheelSeparation>
    <wheelDiameter>0.2</wheelDiameter>
    <torque>0.1</torque>
    <commandTopic>cmd_vel</commandTopic>
    <odometryTopic>odom</odometryTopic>
    <odometryFrame>odom</odometryFrame>
    <robotBaseFrame>link_chassis</robotBaseFrame>
  </plugin>
</gazebo>

  <link name="link_chassis">
    <pose>0 0 0.1 0 0 0</pose>
    <inertial>
      <mass value="5"/>
      <origin rpy="0 0 0" xyz="0 0 0.1"/>
      <inertia
      ixx="0.0395416666667" 
      ixy="0"
      ixz="0"
      iyy="0.106208333333"
      iyz="0"
      izz="0.106208333333"
      />
    </inertial>
    <collision name="collision_chassis">
      <geometry>
        <box size="0.5 0.3 0.07"/>
      </geometry>
    </collision>
    <visual>
      <origin rpy="0 0 0" xyz="0 0 0"/>
      <geometry>
        <box size="0.5 0.3 0.07"/>
      </geometry>
    </visual>
        <collision name="caster_front_collision">
        <origin rpy=" 0 0 0" xyz="0.35 0 -0.05"/>
        <geometry>
            <sphere radius="0.05"/>
        </geometry>
        <surface>
            <friction>
            <ode>
                <mu>0</mu>
                <mu2>0</mu2>
                <slip1>1.0</slip1>
                <slip2>1.0</slip2>
            </ode>
            </friction>
        </surface>
        </collision>
        <visual name="caster_front_visual">
        <origin rpy=" 0 0 0" xyz="0.2 0 -0.05"/>
        <geometry>
            <sphere radius="0.05"/>
        </geometry>
        </visual>
  </link>
  <!--Left wheel, joint-->
<link name="link_left_wheel">
    <inertial>
        <mass value="0.2"/>
        <origin rpy="0 1.5707 1.5707" xyz="0 0 0"/>
        <inertia ixx="0.000526666666667" ixy="0" ixz="0" iyy="0.000526666666667" iyz="0" izz="0.001"/>
    </inertial>
    <collision name="link_right_wheel_collision">
        <origin rpy="0 1.5707 1.5707" xyz="0 0 0"/>
        <geometry>
            <cylinder length="0.04" radius="0.1"/>
        </geometry>
    </collision>
    <visual name="link_left_wheel_visual">
        <origin rpy="0 1.5707 1.5707" xyz="0 0 0"/>
        <geometry>
            <cylinder length="0.04" radius="0.1"/>
        </geometry>
    </visual>
</link>
<joint name="joint_left_wheel" type="continuous">
    <origin rpy="0 0 0" xyz="-0.05 -0.15 0"/>
    <child link="link_left_wheel"/>
    <parent link="link_chassis"/>
    <axis rpy="0 0 0" xyz="0 1 0"/>
    <limit effort="10000" velocity="1000"/>
    <joint_properties damping="1.0" friction="1.0"/>
</joint>
<!--Right wheel, joint-->
<link name="link_right_wheel">
    <inertial>
        <mass value="0.2"/>
        <origin rpy="0 1.5707 1.5707" xyz="0 0 0"/>
        <inertia ixx="0.000526666666667" ixy="0" ixz="0" iyy="0.000526666666667" iyz="0" izz="0.001"/>
    </inertial>
    <collision name="link_right_wheel_collision">
        <origin rpy="0 1.5707 1.5707" xyz="0 0 0"/>
        <geometry>
            <cylinder length="0.04" radius="0.1"/>
        </geometry>
    </collision>
    <visual name="link_right_wheel_visual">
        <origin rpy="0 1.5707 1.5707" xyz="0 0 0"/>
        <geometry>
            <cylinder length="0.04" radius="0.1"/>
        </geometry>
    </visual>
</link>
<joint name="joint_right_wheel" type="continuous">
    <origin rpy="0 0 0" xyz="-0.05 0.15 0"/>
    <child link="link_right_wheel"/>
    <parent link="link_chassis"/>
    <axis rpy="0 0 0" xyz="0 1 0"/>
    <limit effort="10000" velocity="1000"/>
    <joint_properties damping="1.0" friction="1.0"/>
</joint>
<link name="sensor_laser">
  <inertial>
    <origin xyz="0 0 0" rpy="0 0 0" />
    <mass value="0.1" />
    <inertia 	
      ixx="0.00895"
      ixy="0"
      ixz="0"
      iyy="0.00895"
      iyz="0"
      izz="0.00125" />
  </inertial>
  <visual>
    <origin xyz="0 0 0" rpy="0 0 0" />
    <geometry>
      <cylinder length="0.1" radius="0.05"/>
    </geometry>
  </visual>
  <collision>
    <origin xyz="0 0 0" rpy="0 0 0"/>
    <geometry>
      <cylinder length="0.1" radius="0.05"/>
    </geometry>
  </collision>
</link>

<joint name="joint_sensor_laser" type="fixed">
  <origin xyz="0.15 0 0.05" rpy="0 0 0"/>
  <parent link="link_chassis"/>
  <child link="sensor_laser"/>
  <axis xyz="0 0 1"/>
</joint>
<link name="sensor_camera">
  <inertial>
    <origin xyz="0 0 0" rpy="0 0 0" />
    <mass value="0.1" />
    <inertia ixx="0.00895"
             ixy="0"
             ixz="0"
             iyy="0.00895"
             iyz="0"
             izz="0.00125" />
  </inertial>
  <visual>
    <origin xyz="0 0 0" rpy="0 0 0" />
    <geometry>
      <box size="0.02 0.2 0.03"/>
    </geometry>
  </visual>
  <collision>
    <origin xyz="0 0 0" rpy="0 0 0" />
    <geometry>
      <box size="0.02 0.2 0.03"/>
    </geometry>
  </collision>
  </link>
<joint name="joint_sensor_camera" type="fixed">
  <origin xyz="0.25 0 0" rpy="0 0 0"/>
  <parent link="link_chassis"/>
  <child link="sensor_camera"/>
</joint>

</robot>
